<?xml version='1.0' encoding='utf-8'?>
<robot name="leap_rh">
  <material name="black">
    <color rgba="0.05 0.05 0.05 1" />
  </material>
  <material name="white">
    <color rgba="1 1 1 1" />
  </material>
  <link name="base" />
  <link name="palm">
    <inertial>
      <origin xyz="-0.049542 -0.042914 -0.010227" rpy="0.000000 0.000000 0.000000" />
      <mass value="0.237000" />
      <inertia ixx="0.000293510" iyy="0.000192170" izz="0.000407160" ixy="-0.000035625" ixz="-0.000000439" iyz="-0.000006247" />
    </inertial>
    <visual>
      <origin xyz="-0.020000 0.025750 -0.034700" rpy="0.000000 0.000000 0.000000" />
      <geometry>
        <mesh filename="../mjcf/assets/palm_right.obj" />
      </geometry>
      <material name="black">
        <color rgba="0.05 0.05 0.05 1" />
      </material>
    </visual>
    <collision>
      <origin xyz="-0.009000 0.008000 -0.011000" rpy="0.000000 0.000000 0.000000" />
      <geometry>
        <box size="0.022000 0.026000 0.034000" />
      </geometry>
    </collision>
    <collision>
      <origin xyz="-0.009000 -0.037000 -0.011000" rpy="0.000000 0.000000 0.000000" />
      <geometry>
        <box size="0.022000 0.026000 0.034000" />
      </geometry>
    </collision>
    <collision>
      <origin xyz="-0.009000 -0.082000 -0.011000" rpy="0.000000 0.000000 0.000000" />
      <geometry>
        <box size="0.022000 0.026000 0.034000" />
      </geometry>
    </collision>
    <collision>
      <origin xyz="-0.066000 -0.078000 -0.011500" rpy="0.000000 0.000000 -0.296699" />
      <geometry>
        <box size="0.058000 0.020000 0.046000" />
      </geometry>
    </collision>
    <collision>
      <origin xyz="-0.030000 -0.035000 -0.003000" rpy="0.000000 0.000000 0.000000" />
      <geometry>
        <box size="0.020000 0.120000 0.030000" />
      </geometry>
    </collision>
    <collision>
      <origin xyz="-0.032000 -0.035000 -0.024000" rpy="0.000000 0.784999 0.000000" />
      <geometry>
        <box size="0.010000 0.120000 0.020000" />
      </geometry>
    </collision>
    <collision>
      <origin xyz="-0.048000 -0.033000 -0.011500" rpy="0.000000 0.000000 0.000000" />
      <geometry>
        <box size="0.024000 0.116000 0.046000" />
      </geometry>
    </collision>
    <collision>
      <origin xyz="-0.078000 -0.053000 -0.011500" rpy="0.000000 0.000000 0.000000" />
      <geometry>
        <box size="0.044000 0.052000 0.046000" />
      </geometry>
    </collision>
    <collision>
      <origin xyz="-0.098000 -0.009000 -0.006000" rpy="0.000000 0.000000 0.000000" />
      <geometry>
        <box size="0.004000 0.036000 0.034000" />
      </geometry>
    </collision>
    <collision>
      <origin xyz="-0.078000 -0.003000 0.010000" rpy="0.000000 0.000000 0.000000" />
      <geometry>
        <box size="0.044000 0.056000 0.004000" />
      </geometry>
    </collision>
  </link>
  <joint name="base_palm_fixed" type="fixed">
    <parent link="base" />
    <child link="palm" />
    <origin xyz="0.057595 -0.033342 0.011278" rpy="3.141593 0.000000 0.000000" />
  </joint>
  <link name="if_bs">
    <inertial>
      <origin xyz="-0.022516 0.033882 0.016359" rpy="0.000000 0.000000 0.000000" />
      <mass value="0.044000" />
      <inertia ixx="0.000013160" iyy="0.000010301" izz="0.000017400" ixy="0.000004266" ixz="0.000000507" iyz="-0.000000162" />
    </inertial>
    <visual>
      <origin xyz="0.008400 0.007700 0.014650" rpy="0.000000 0.000000 0.000000" />
      <geometry>
        <mesh filename="../mjcf/assets/base.obj" />
      </geometry>
      <material name="black">
        <color rgba="0.05 0.05 0.05 1" />
      </material>
    </visual>
    <collision>
      <origin xyz="0.000000 0.018000 0.014700" rpy="0.000000 0.000000 0.000000" />
      <geometry>
        <box size="0.020000 0.006000 0.034000" />
      </geometry>
    </collision>
    <collision>
      <origin xyz="-0.027000 0.042000 0.015000" rpy="0.000000 0.000000 0.000000" />
      <geometry>
        <box size="0.028000 0.040000 0.020000" />
      </geometry>
    </collision>
    <collision>
      <origin xyz="-0.026200 0.020000 0.014600" rpy="0.000000 0.000000 0.000000" />
      <geometry>
        <box size="0.034000 0.006000 0.020000" />
      </geometry>
    </collision>
    <collision>
      <origin xyz="-0.029500 0.035000 0.029000" rpy="0.000000 0.000000 0.000000" />
      <geometry>
        <box size="0.020000 0.024000 0.008000" />
      </geometry>
    </collision>
    <collision>
      <origin xyz="0.000000 0.005000 0.030000" rpy="0.000000 0.000000 0.000000" />
      <geometry>
        <box size="0.014000 0.020000 0.004000" />
      </geometry>
    </collision>
    <collision>
      <origin xyz="0.000000 0.005000 -0.001000" rpy="0.000000 0.000000 0.000000" />
      <geometry>
        <box size="0.014000 0.020000 0.004000" />
      </geometry>
    </collision>
  </link>
  <joint name="if_mcp" type="revolute">
    <parent link="palm" />
    <child link="if_bs" />
    <origin xyz="-0.007000 0.023000 -0.018700" rpy="1.570796 1.570796 0.000003" />
    <axis xyz="0.000000 0.000000 -1.000000" />
    <!-- <dynamics damping="0.030000" friction="0.001000" /> -->
    <limit effort="0.5" velocity="8" lower="-0.314000" upper="2.230000" />
  </joint>
  <link name="if_px">
    <inertial>
      <origin xyz="0.007500 -0.000200 -0.011000" rpy="0.000000 0.000000 0.000000" />
      <mass value="0.032000" />
      <inertia ixx="0.000003093" iyy="0.000004373" izz="0.000004885" ixy="0.000000000" ixz="-0.000000000" iyz="0.000000000" />
    </inertial>
    <visual>
      <origin xyz="0.009600 0.000200 0.000700" rpy="-1.570796 -1.570796 0.000003" />
      <geometry>
        <mesh filename="../mjcf/assets/proximal.obj" />
      </geometry>
      <material name="black">
        <color rgba="0.05 0.05 0.05 1" />
      </material>
    </visual>
    <collision>
      <origin xyz="0.007500 -0.000200 -0.011000" rpy="0.000000 0.000000 0.000000" />
      <geometry>
        <box size="0.034000 0.026000 0.022000" />
      </geometry>
    </collision>
  </link>
  <joint name="if_rot" type="revolute">
    <parent link="if_bs" />
    <child link="if_px" />
    <origin xyz="-0.012200 0.038100 0.014500" rpy="-1.570790 0.000000 1.570790" />
    <axis xyz="0.000000 0.000000 -1.000000" />
    <!-- <dynamics damping="0.030000" friction="0.001000" /> -->
    <limit effort="0.5" velocity="8" lower="-1.047000" upper="1.047000" />
  </joint>
  <link name="if_md">
    <inertial>
      <origin xyz="0.005422 -0.029148 0.015000" rpy="0.000000 0.000000 0.000000" />
      <mass value="0.037000" />
      <inertia ixx="0.000007676" iyy="0.000005999" izz="0.000008160" ixy="0.000001174" ixz="-0.000000000" iyz="-0.000000000" />
    </inertial>
    <visual>
      <origin xyz="0.021100 -0.008400 0.009700" rpy="-3.141593 0.000000 0.000000" />
      <geometry>
        <mesh filename="../mjcf/assets/medial.obj" />
      </geometry>
      <material name="black">
        <color rgba="0.05 0.05 0.05 1" />
      </material>
    </visual>
    <collision>
      <origin xyz="0.000000 -0.020000 0.015000" rpy="0.000000 0.000000 0.000000" />
      <geometry>
        <box size="0.016000 0.006000 0.026000" />
      </geometry>
    </collision>
    <collision>
      <origin xyz="0.000000 -0.016000 0.015000" rpy="0.000000 0.000000 0.000000" />
      <geometry>
        <box size="0.020000 0.004000 0.034000" />
      </geometry>
    </collision>
    <collision>
      <origin xyz="0.000000 -0.004500 0.030000" rpy="0.000000 0.000000 0.000000" />
      <geometry>
        <box size="0.014000 0.020000 0.004000" />
      </geometry>
    </collision>
    <collision>
      <origin xyz="0.000000 -0.004500 0.000000" rpy="0.000000 0.000000 0.000000" />
      <geometry>
        <box size="0.014000 0.020000 0.004000" />
      </geometry>
    </collision>
    <collision>
      <origin xyz="0.007500 -0.035000 0.015000" rpy="0.000000 0.000000 0.000000" />
      <geometry>
        <box size="0.034000 0.022000 0.026000" />
      </geometry>
    </collision>
  </link>
  <joint name="if_pip" type="revolute">
    <parent link="if_px" />
    <child link="if_md" />
    <origin xyz="0.015000 0.014300 -0.013000" rpy="1.570796 -1.570796 -0.000003" />
    <axis xyz="0.000000 0.000000 -1.000000" />
    <!-- <dynamics damping="0.030000" friction="0.001000" /> -->
    <limit effort="0.5" velocity="8" lower="-0.506000" upper="1.885000" />
  </joint>
  <link name="if_ds">
    <inertial>
      <origin xyz="-0.000879 -0.027019 0.014594" rpy="0.000000 0.000000 0.000000" />
      <mass value="0.016000" />
      <inertia ixx="0.000003711" iyy="0.000001660" izz="0.000003024" ixy="-0.000000125" ixz="-0.000000001" iyz="-0.000000015" />
    </inertial>
    <visual>
      <origin xyz="0.013200 -0.006100 0.014400" rpy="3.141593 0.000000 0.000000" />
      <geometry>
        <mesh filename="../mjcf/assets/distal.obj" />
      </geometry>
      <material name="black">
        <color rgba="0.05 0.05 0.05 1" />
      </material>
    </visual>
    <collision>
      <origin xyz="0.000000 -0.017000 0.015000" rpy="0.000000 0.000000 0.000000" />
      <geometry>
        <box size="0.020000 0.006000 0.030000" />
      </geometry>
    </collision>
    <collision>
      <origin xyz="0.000000 -0.006000 0.030000" rpy="0.000000 0.000000 0.000000" />
      <geometry>
        <box size="0.014000 0.022000 0.004000" />
      </geometry>
    </collision>
    <collision>
      <origin xyz="0.000000 -0.006000 -0.001000" rpy="0.000000 0.000000 0.000000" />
      <geometry>
        <box size="0.014000 0.022000 0.004000" />
      </geometry>
    </collision>
    <visual>
      <origin xyz="0.000000 0.000000 0.000000" rpy="0.000000 0.000000 0.000000" />
      <geometry>
        <mesh filename="../mjcf/assets/tip.obj" />
      </geometry>
      <material name="black">
        <color rgba="0.05 0.05 0.05 1" />
      </material>
    </visual>
    <collision>
      <origin xyz="0.000000 0.000000 0.000000" rpy="0.000000 0.000000 0.000000" />
      <geometry>
        <mesh filename="../mjcf/assets/tip.obj" />
      </geometry>
    </collision>
  </link>
  <joint name="if_dip" type="revolute">
    <parent link="if_md" />
    <child link="if_ds" />
    <origin xyz="0.000000 -0.036100 0.000200" rpy="0.000000 0.000000 0.000000" />
    <axis xyz="0.000000 0.000000 -1.000000" />
    <!-- <dynamics damping="0.030000" friction="0.001000" /> -->
    <limit effort="0.5" velocity="8" lower="-0.366000" upper="2.042000" />
  </joint>
  <link name="mf_bs">
    <inertial>
      <origin xyz="-0.022516 0.033882 0.016359" rpy="0.000000 0.000000 0.000000" />
      <mass value="0.044000" />
      <inertia ixx="0.000013160" iyy="0.000010301" izz="0.000017400" ixy="0.000004266" ixz="0.000000507" iyz="-0.000000162" />
    </inertial>
    <visual>
      <origin xyz="0.008400 0.007700 0.014650" rpy="0.000000 0.000000 0.000000" />
      <geometry>
        <mesh filename="../mjcf/assets/base.obj" />
      </geometry>
      <material name="black">
        <color rgba="0.05 0.05 0.05 1" />
      </material>
    </visual>
    <collision>
      <origin xyz="0.000000 0.018000 0.014700" rpy="0.000000 0.000000 0.000000" />
      <geometry>
        <box size="0.020000 0.006000 0.034000" />
      </geometry>
    </collision>
    <collision>
      <origin xyz="-0.027000 0.042000 0.015000" rpy="0.000000 0.000000 0.000000" />
      <geometry>
        <box size="0.028000 0.040000 0.020000" />
      </geometry>
    </collision>
    <collision>
      <origin xyz="-0.026200 0.020000 0.014600" rpy="0.000000 0.000000 0.000000" />
      <geometry>
        <box size="0.034000 0.006000 0.020000" />
      </geometry>
    </collision>
    <collision>
      <origin xyz="-0.029500 0.035000 0.029000" rpy="0.000000 0.000000 0.000000" />
      <geometry>
        <box size="0.020000 0.024000 0.008000" />
      </geometry>
    </collision>
    <collision>
      <origin xyz="0.000000 0.005000 0.030000" rpy="0.000000 0.000000 0.000000" />
      <geometry>
        <box size="0.014000 0.020000 0.004000" />
      </geometry>
    </collision>
    <collision>
      <origin xyz="0.000000 0.005000 -0.001000" rpy="0.000000 0.000000 0.000000" />
      <geometry>
        <box size="0.014000 0.020000 0.004000" />
      </geometry>
    </collision>
  </link>
  <joint name="mf_mcp" type="revolute">
    <parent link="palm" />
    <child link="mf_bs" />
    <origin xyz="-0.007100 -0.022400 -0.018700" rpy="1.570796 1.570796 0.000003" />
    <axis xyz="0.000000 0.000000 -1.000000" />
    <!-- <dynamics damping="0.030000" friction="0.001000" /> -->
    <limit effort="0.5" velocity="8" lower="-0.314000" upper="2.230000" />
  </joint>
  <link name="mf_px">
    <inertial>
      <origin xyz="0.007500 -0.000200 -0.011000" rpy="0.000000 0.000000 0.000000" />
      <mass value="0.032000" />
      <inertia ixx="0.000003093" iyy="0.000004373" izz="0.000004885" ixy="0.000000000" ixz="-0.000000000" iyz="0.000000000" />
    </inertial>
    <visual>
      <origin xyz="0.009600 0.000300 0.000700" rpy="-1.570796 -1.570796 0.000003" />
      <geometry>
        <mesh filename="../mjcf/assets/proximal.obj" />
      </geometry>
      <material name="black">
        <color rgba="0.05 0.05 0.05 1" />
      </material>
    </visual>
    <collision>
      <origin xyz="0.007500 -0.000200 -0.011000" rpy="0.000000 0.000000 0.000000" />
      <geometry>
        <box size="0.034000 0.026000 0.022000" />
      </geometry>
    </collision>
  </link>
  <joint name="mf_rot" type="revolute">
    <parent link="mf_bs" />
    <child link="mf_px" />
    <origin xyz="-0.012200 0.038100 0.014500" rpy="-1.570790 0.000000 1.570790" />
    <axis xyz="0.000000 0.000000 -1.000000" />
    <!-- <dynamics damping="0.030000" friction="0.001000" /> -->
    <limit effort="0.5" velocity="8" lower="-1.047000" upper="1.047000" />
  </joint>
  <link name="mf_md">
    <inertial>
      <origin xyz="0.005422 -0.029148 0.015000" rpy="0.000000 0.000000 0.000000" />
      <mass value="0.037000" />
      <inertia ixx="0.000007676" iyy="0.000005999" izz="0.000008160" ixy="0.000001174" ixz="-0.000000000" iyz="-0.000000000" />
    </inertial>
    <visual>
      <origin xyz="0.021100 -0.008400 0.009700" rpy="-3.141590 0.000000 0.000000" />
      <geometry>
        <mesh filename="../mjcf/assets/medial.obj" />
      </geometry>
      <material name="black">
        <color rgba="0.05 0.05 0.05 1" />
      </material>
    </visual>
    <collision>
      <origin xyz="0.000000 -0.020000 0.015000" rpy="0.000000 0.000000 0.000000" />
      <geometry>
        <box size="0.016000 0.006000 0.026000" />
      </geometry>
    </collision>
    <collision>
      <origin xyz="0.000000 -0.016000 0.015000" rpy="0.000000 0.000000 0.000000" />
      <geometry>
        <box size="0.020000 0.004000 0.034000" />
      </geometry>
    </collision>
    <collision>
      <origin xyz="0.000000 -0.004500 0.030000" rpy="0.000000 0.000000 0.000000" />
      <geometry>
        <box size="0.014000 0.020000 0.004000" />
      </geometry>
    </collision>
    <collision>
      <origin xyz="0.000000 -0.004500 0.000000" rpy="0.000000 0.000000 0.000000" />
      <geometry>
        <box size="0.014000 0.020000 0.004000" />
      </geometry>
    </collision>
    <collision>
      <origin xyz="0.007500 -0.035000 0.015000" rpy="0.000000 0.000000 0.000000" />
      <geometry>
        <box size="0.034000 0.022000 0.026000" />
      </geometry>
    </collision>
  </link>
  <joint name="mf_pip" type="revolute">
    <parent link="mf_px" />
    <child link="mf_md" />
    <origin xyz="0.015000 0.014300 -0.013000" rpy="1.570796 -1.570796 -0.000003" />
    <axis xyz="0.000000 0.000000 -1.000000" />
    <!-- <dynamics damping="0.030000" friction="0.001000" /> -->
    <limit effort="0.5" velocity="8" lower="-0.506000" upper="1.885000" />
  </joint>
  <link name="mf_ds">
    <inertial>
      <origin xyz="-0.000879 -0.027019 0.014594" rpy="0.000000 0.000000 0.000000" />
      <mass value="0.016000" />
      <inertia ixx="0.000003711" iyy="0.000001660" izz="0.000003024" ixy="-0.000000125" ixz="-0.000000001" iyz="-0.000000015" />
    </inertial>
    <visual>
      <origin xyz="0.013200 -0.006100 0.014500" rpy="3.141590 0.000000 0.000000" />
      <geometry>
        <mesh filename="../mjcf/assets/distal.obj" />
      </geometry>
      <material name="black">
        <color rgba="0.05 0.05 0.05 1" />
      </material>
    </visual>
    <collision>
      <origin xyz="0.000000 -0.017000 0.015000" rpy="0.000000 0.000000 0.000000" />
      <geometry>
        <box size="0.020000 0.006000 0.030000" />
      </geometry>
    </collision>
    <collision>
      <origin xyz="0.000000 -0.006000 0.030000" rpy="0.000000 0.000000 0.000000" />
      <geometry>
        <box size="0.014000 0.022000 0.004000" />
      </geometry>
    </collision>
    <collision>
      <origin xyz="0.000000 -0.006000 -0.001000" rpy="0.000000 0.000000 0.000000" />
      <geometry>
        <box size="0.014000 0.022000 0.004000" />
      </geometry>
    </collision>
    <visual>
      <origin xyz="0.000000 0.000000 0.000000" rpy="0.000000 0.000000 0.000000" />
      <geometry>
        <mesh filename="../mjcf/assets/tip.obj" />
      </geometry>
      <material name="black">
        <color rgba="0.05 0.05 0.05 1" />
      </material>
    </visual>
    <collision>
      <origin xyz="0.000000 0.000000 0.000000" rpy="0.000000 0.000000 0.000000" />
      <geometry>
        <mesh filename="../mjcf/assets/tip.obj" />
      </geometry>
    </collision>
  </link>
  <joint name="mf_dip" type="revolute">
    <parent link="mf_md" />
    <child link="mf_ds" />
    <origin xyz="0.000000 -0.036100 0.000200" rpy="0.000000 0.000000 0.000000" />
    <axis xyz="0.000000 0.000000 -1.000000" />
    <!-- <dynamics damping="0.030000" friction="0.001000" /> -->
    <limit effort="0.5" velocity="8" lower="-0.366000" upper="2.042000" />
  </joint>
  <link name="rf_bs">
    <inertial>
      <origin xyz="-0.022516 0.033882 0.016359" rpy="0.000000 0.000000 0.000000" />
      <mass value="0.044000" />
      <inertia ixx="0.000013160" iyy="0.000010301" izz="0.000017400" ixy="0.000004266" ixz="0.000000507" iyz="-0.000000162" />
    </inertial>
    <visual>
      <origin xyz="0.008400 0.007700 0.014650" rpy="0.000000 0.000000 0.000000" />
      <geometry>
        <mesh filename="../mjcf/assets/base.obj" />
      </geometry>
      <material name="black">
        <color rgba="0.05 0.05 0.05 1" />
      </material>
    </visual>
    <collision>
      <origin xyz="0.000000 0.018000 0.014700" rpy="0.000000 0.000000 0.000000" />
      <geometry>
        <box size="0.020000 0.006000 0.034000" />
      </geometry>
    </collision>
    <collision>
      <origin xyz="-0.027000 0.042000 0.015000" rpy="0.000000 0.000000 0.000000" />
      <geometry>
        <box size="0.028000 0.040000 0.020000" />
      </geometry>
    </collision>
    <collision>
      <origin xyz="-0.026200 0.020000 0.014600" rpy="0.000000 0.000000 0.000000" />
      <geometry>
        <box size="0.034000 0.006000 0.020000" />
      </geometry>
    </collision>
    <collision>
      <origin xyz="-0.029500 0.035000 0.029000" rpy="0.000000 0.000000 0.000000" />
      <geometry>
        <box size="0.020000 0.024000 0.008000" />
      </geometry>
    </collision>
    <collision>
      <origin xyz="0.000000 0.005000 0.030000" rpy="0.000000 0.000000 0.000000" />
      <geometry>
        <box size="0.014000 0.020000 0.004000" />
      </geometry>
    </collision>
    <collision>
      <origin xyz="0.000000 0.005000 -0.001000" rpy="0.000000 0.000000 0.000000" />
      <geometry>
        <box size="0.014000 0.020000 0.004000" />
      </geometry>
    </collision>
  </link>
  <joint name="rf_mcp" type="revolute">
    <parent link="palm" />
    <child link="rf_bs" />
    <origin xyz="-0.007090 -0.067800 -0.018700" rpy="1.570796 1.570796 0.000003" />
    <axis xyz="0.000000 0.000000 -1.000000" />
    <!-- <dynamics damping="0.030000" friction="0.001000" /> -->
    <limit effort="0.5" velocity="8" lower="-0.314000" upper="2.230000" />
  </joint>
  <link name="rf_px">
    <inertial>
      <origin xyz="0.007500 -0.000200 -0.011000" rpy="0.000000 0.000000 0.000000" />
      <mass value="0.032000" />
      <inertia ixx="0.000003093" iyy="0.000004373" izz="0.000004885" ixy="0.000000000" ixz="-0.000000000" iyz="0.000000000" />
    </inertial>
    <visual>
      <origin xyz="0.009600 0.000300 0.000700" rpy="-1.570796 -1.570796 0.000003" />
      <geometry>
        <mesh filename="../mjcf/assets/proximal.obj" />
      </geometry>
      <material name="black">
        <color rgba="0.05 0.05 0.05 1" />
      </material>
    </visual>
    <collision>
      <origin xyz="0.007500 -0.000200 -0.011000" rpy="0.000000 0.000000 0.000000" />
      <geometry>
        <box size="0.034000 0.026000 0.022000" />
      </geometry>
    </collision>
  </link>
  <joint name="rf_rot" type="revolute">
    <parent link="rf_bs" />
    <child link="rf_px" />
    <origin xyz="-0.012200 0.038100 0.014500" rpy="-1.570790 0.000000 1.570790" />
    <axis xyz="0.000000 0.000000 -1.000000" />
    <!-- <dynamics damping="0.030000" friction="0.001000" /> -->
    <limit effort="0.5" velocity="8" lower="-1.047000" upper="1.047000" />
  </joint>
  <link name="rf_md">
    <inertial>
      <origin xyz="0.005422 -0.029148 0.015000" rpy="0.000000 0.000000 0.000000" />
      <mass value="0.037000" />
      <inertia ixx="0.000007676" iyy="0.000005999" izz="0.000008160" ixy="0.000001174" ixz="-0.000000000" iyz="-0.000000000" />
    </inertial>
    <visual>
      <origin xyz="0.021100 -0.008400 0.009700" rpy="-3.141590 0.000000 0.000000" />
      <geometry>
        <mesh filename="../mjcf/assets/medial.obj" />
      </geometry>
      <material name="black">
        <color rgba="0.05 0.05 0.05 1" />
      </material>
    </visual>
    <collision>
      <origin xyz="0.000000 -0.020000 0.015000" rpy="0.000000 0.000000 0.000000" />
      <geometry>
        <box size="0.016000 0.006000 0.026000" />
      </geometry>
    </collision>
    <collision>
      <origin xyz="0.000000 -0.016000 0.015000" rpy="0.000000 0.000000 0.000000" />
      <geometry>
        <box size="0.020000 0.004000 0.034000" />
      </geometry>
    </collision>
    <collision>
      <origin xyz="0.000000 -0.004500 0.030000" rpy="0.000000 0.000000 0.000000" />
      <geometry>
        <box size="0.014000 0.020000 0.004000" />
      </geometry>
    </collision>
    <collision>
      <origin xyz="0.000000 -0.004500 0.000000" rpy="0.000000 0.000000 0.000000" />
      <geometry>
        <box size="0.014000 0.020000 0.004000" />
      </geometry>
    </collision>
    <collision>
      <origin xyz="0.007500 -0.035000 0.015000" rpy="0.000000 0.000000 0.000000" />
      <geometry>
        <box size="0.034000 0.022000 0.026000" />
      </geometry>
    </collision>
  </link>
  <joint name="rf_pip" type="revolute">
    <parent link="rf_px" />
    <child link="rf_md" />
    <origin xyz="0.015000 0.014300 -0.013000" rpy="1.570796 -1.570796 -0.000003" />
    <axis xyz="0.000000 0.000000 -1.000000" />
    <!-- <dynamics damping="0.030000" friction="0.001000" /> -->
    <limit effort="0.5" velocity="8" lower="-0.506000" upper="1.885000" />
  </joint>
  <link name="rf_ds">
    <inertial>
      <origin xyz="-0.000879 -0.027019 0.014594" rpy="0.000000 0.000000 0.000000" />
      <mass value="0.016000" />
      <inertia ixx="0.000003711" iyy="0.000001660" izz="0.000003024" ixy="-0.000000125" ixz="-0.000000001" iyz="-0.000000015" />
    </inertial>
    <visual>
      <origin xyz="0.013200 -0.006100 0.014500" rpy="3.141590 0.000000 0.000000" />
      <geometry>
        <mesh filename="../mjcf/assets/distal.obj" />
      </geometry>
      <material name="black">
        <color rgba="0.05 0.05 0.05 1" />
      </material>
    </visual>
    <collision>
      <origin xyz="0.000000 -0.017000 0.015000" rpy="0.000000 0.000000 0.000000" />
      <geometry>
        <box size="0.020000 0.006000 0.030000" />
      </geometry>
    </collision>
    <collision>
      <origin xyz="0.000000 -0.006000 0.030000" rpy="0.000000 0.000000 0.000000" />
      <geometry>
        <box size="0.014000 0.022000 0.004000" />
      </geometry>
    </collision>
    <collision>
      <origin xyz="0.000000 -0.006000 -0.001000" rpy="0.000000 0.000000 0.000000" />
      <geometry>
        <box size="0.014000 0.022000 0.004000" />
      </geometry>
    </collision>
    <visual>
      <origin xyz="0.000000 0.000000 0.000000" rpy="0.000000 0.000000 0.000000" />
      <geometry>
        <mesh filename="../mjcf/assets/tip.obj" />
      </geometry>
      <material name="black">
        <color rgba="0.05 0.05 0.05 1" />
      </material>
    </visual>
    <collision>
      <origin xyz="0.000000 0.000000 0.000000" rpy="0.000000 0.000000 0.000000" />
      <geometry>
        <mesh filename="../mjcf/assets/tip.obj" />
      </geometry>
    </collision>
  </link>
  <joint name="rf_dip" type="revolute">
    <parent link="rf_md" />
    <child link="rf_ds" />
    <origin xyz="0.000000 -0.036090 0.000200" rpy="0.000000 0.000000 0.000000" />
    <axis xyz="0.000000 0.000000 -1.000000" />
    <!-- <dynamics damping="0.030000" friction="0.001000" /> -->
    <limit effort="0.5" velocity="8" lower="-0.366000" upper="2.042000" />
  </joint>
  <link name="th_mp">
    <inertial>
      <origin xyz="0.007500 -0.000200 -0.011000" rpy="0.000000 0.000000 0.000000" />
      <mass value="0.032000" />
      <inertia ixx="0.000003093" iyy="0.000004373" izz="0.000004885" ixy="0.000000000" ixz="-0.000000000" iyz="0.000000000" />
    </inertial>
    <visual>
      <origin xyz="-0.005300 0.000300 0.000780" rpy="-1.570796 -1.570796 0.000003" />
      <geometry>
        <mesh filename="../mjcf/assets/proximal.obj" />
      </geometry>
      <material name="black">
        <color rgba="0.05 0.05 0.05 1" />
      </material>
    </visual>
    <collision>
      <origin xyz="-0.007500 -0.000200 -0.011000" rpy="0.000000 0.000000 0.000000" />
      <geometry>
        <box size="0.034000 0.026000 0.022000" />
      </geometry>
    </collision>
  </link>
  <joint name="th_cmc" type="revolute">
    <parent link="palm" />
    <child link="th_mp" />
    <origin xyz="-0.069300 -0.001200 -0.021600" rpy="0.000000 1.570796 0.000000" />
    <axis xyz="0.000000 0.000000 -1.000000" />
    <!-- <dynamics damping="0.030000" friction="0.001000" /> -->
    <limit effort="0.5" velocity="8" lower="-0.349000" upper="2.094000" />
  </joint>
  <link name="th_bs">
    <inertial>
      <origin xyz="0.000000 0.000000 -0.007081" rpy="0.000000 0.000000 0.000000" />
      <mass value="0.003000" />
      <inertia ixx="0.000000619" iyy="0.000000215" izz="0.000000535" ixy="0.000000000" ixz="0.000000000" iyz="-0.000000000" />
    </inertial>
    <visual>
      <origin xyz="0.011960 0.000000 -0.015800" rpy="1.570791 0.000000 0.000000" />
      <geometry>
        <mesh filename="../mjcf/assets/thumb_base.obj" />
      </geometry>
      <material name="black">
        <color rgba="0.05 0.05 0.05 1" />
      </material>
    </visual>
    <collision>
      <origin xyz="0.000000 0.000000 -0.001500" rpy="0.000000 0.000000 0.000000" />
      <geometry>
        <box size="0.018000 0.033000 0.004000" />
      </geometry>
    </collision>
    <collision>
      <origin xyz="0.000000 -0.015000 -0.013000" rpy="0.000000 0.000000 0.000000" />
      <geometry>
        <box size="0.014000 0.004000 0.020000" />
      </geometry>
    </collision>
    <collision>
      <origin xyz="0.000000 0.015000 -0.013000" rpy="0.000000 0.000000 0.000000" />
      <geometry>
        <box size="0.014000 0.004000 0.020000" />
      </geometry>
    </collision>
  </link>
  <joint name="th_axl" type="revolute">
    <parent link="th_mp" />
    <child link="th_bs" />
    <origin xyz="0.000000 0.014300 -0.013000" rpy="1.570796 -1.570796 -0.000003" />
    <axis xyz="0.000000 0.000000 -1.000000" />
    <!-- <dynamics damping="0.030000" friction="0.001000" /> -->
    <limit effort="0.5" velocity="8" lower="-0.349000" upper="2.094000" />
  </joint>
  <link name="th_px">
    <inertial>
      <origin xyz="-0.002059 0.015912 -0.013733" rpy="0.000000 0.000000 0.000000" />
      <mass value="0.038000" />
      <inertia ixx="0.000009814" iyy="0.000004365" izz="0.000009381" ixy="0.000000124" ixz="0.000000163" iyz="0.000000030" />
    </inertial>
    <visual>
      <origin xyz="0.043900 0.057900 -0.008600" rpy="0.000000 0.000000 0.000000" />
      <geometry>
        <mesh filename="../mjcf/assets/thumb_proximal.obj" />
      </geometry>
      <material name="black">
        <color rgba="0.05 0.05 0.05 1" />
      </material>
    </visual>
    <collision>
      <origin xyz="0.000000 0.010500 -0.014000" rpy="0.000000 0.000000 0.000000" />
      <geometry>
        <box size="0.020000 0.040000 0.024000" />
      </geometry>
    </collision>
    <collision>
      <origin xyz="0.000000 0.031000 -0.015000" rpy="0.000000 0.000000 0.000000" />
      <geometry>
        <box size="0.020000 0.004000 0.032000" />
      </geometry>
    </collision>
    <collision>
      <origin xyz="0.000000 0.042000 0.001000" rpy="0.000000 0.000000 0.000000" />
      <geometry>
        <box size="0.014000 0.020000 0.004000" />
      </geometry>
    </collision>
    <collision>
      <origin xyz="0.000000 0.042000 -0.029000" rpy="0.000000 0.000000 0.000000" />
      <geometry>
        <box size="0.014000 0.020000 0.004000" />
      </geometry>
    </collision>
    <collision>
      <origin xyz="-0.013500 0.017500 -0.011656" rpy="0.000000 0.000000 0.000000" />
      <geometry>
        <box size="0.010000 0.024000 0.018000" />
      </geometry>
    </collision>
  </link>
  <joint name="th_mcp" type="revolute">
    <parent link="th_bs" />
    <child link="th_px" />
    <origin xyz="0.000000 0.014500 -0.017000" rpy="-1.570791 0.000000 0.000000" />
    <axis xyz="0.000000 0.000000 -1.000000" />
    <!-- <dynamics damping="0.030000" friction="0.001000" /> -->
    <limit effort="0.5" velocity="8" lower="-0.470000" upper="2.443000" />
  </joint>
  <link name="th_ds">
    <inertial>
      <origin xyz="0.000962 -0.024203 -0.014419" rpy="0.000000 0.000000 0.000000" />
      <mass value="0.049000" />
      <inertia ixx="0.000020480" iyy="0.000004778" izz="0.000020716" ixy="-0.000001009" ixz="-0.000000206" iyz="0.000000097" />
    </inertial>
    <visual>
      <origin xyz="0.062500 0.078400 0.048900" rpy="0.000000 0.000000 0.000000" />
      <geometry>
        <mesh filename="../mjcf/assets/thumb_distal.obj" />
      </geometry>
      <material name="black">
        <color rgba="0.05 0.05 0.05 1" />
      </material>
    </visual>
    <collision>
      <origin xyz="0.000000 -0.008500 -0.015000" rpy="0.000000 0.000000 0.000000" />
      <geometry>
        <box size="0.020000 0.036000 0.024000" />
      </geometry>
    </collision>
    <collision>
      <origin xyz="0.000000 -0.029000 -0.014000" rpy="0.000000 0.000000 0.000000" />
      <geometry>
        <box size="0.020000 0.004000 0.030000" />
      </geometry>
    </collision>
    <collision>
      <origin xyz="0.015000 -0.017500 -0.011500" rpy="0.000000 0.000000 0.000000" />
      <geometry>
        <box size="0.008000 0.024000 0.018000" />
      </geometry>
    </collision>
    <visual>
      <origin xyz="0.000000 0.000000 0.000000" rpy="0.000000 0.000000 0.000000" />
      <geometry>
        <mesh filename="../mjcf/assets/thumb_tip.obj" />
      </geometry>
      <material name="black">
        <color rgba="0.05 0.05 0.05 1" />
      </material>
    </visual>
    <collision>
      <origin xyz="0.000000 0.000000 0.000000" rpy="0.000000 0.000000 0.000000" />
      <geometry>
        <mesh filename="../mjcf/assets/thumb_tip.obj" />
      </geometry>
    </collision>
  </link>
  <joint name="th_ipl" type="revolute">
    <parent link="th_px" />
    <child link="th_ds" />
    <origin xyz="0.000000 0.046600 0.000200" rpy="0.000000 0.000000 3.141590" />
    <axis xyz="0.000000 0.000000 -1.000000" />
    <!-- <dynamics damping="0.030000" friction="0.001000" /> -->
    <limit effort="0.5" velocity="8" lower="-1.340000" upper="1.880000" />
  </joint>
</robot>